Traceback (most recent call last):
  File "/home/debian/code/Rud.py", line 51, in call
    a3la.expect('CONNECT', wait=15)
A3la.ExpectError
Traceback (most recent call last):
  File "/home/debian/code/Rud.py", line 51, in call
    a3la.expect('CONNECT', wait=15)
A3la.ExpectError

During handling of the above exception, another exception occurred:

Traceback (most recent call last):
  File "/home/debian/code/Rud.py", line 51, in call
    a3la.expect('CONNECT', wait=15)
A3la.ExpectError
Traceback (most recent call last):
  File "/home/debian/code/Rud.py", line 51, in call
    a3la.expect('CONNECT', wait=15)
A3la.ExpectError

During handling of the above exception, another exception occurred:

Traceback (most recent call last):
  File "/home/debian/code/Rud.py", line 51, in call
    a3la.expect('CONNECT', wait=15)
A3la.ExpectError

During handling of the above exception, another exception occurred:

Traceback (most recent call last):
  File "/home/debian/code/Rud.py", line 51, in call
    a3la.expect('CONNECT', wait=15)
A3la.ExpectError
Traceback (most recent call last):
  File "/home/debian/code/Rud.py", line 51, in call
    a3la.expect('CONNECT', wait=15)
A3la.ExpectError

During handling of the above exception, another exception occurred:

Traceback (most recent call last):
  File "/home/debian/code/Rud.py", line 51, in call
    a3la.expect('CONNECT', wait=15)
A3la.ExpectError

During handling of the above exception, another exception occurred:

Traceback (most recent call last):
  File "/home/debian/code/Rud.py", line 51, in call
    a3la.expect('CONNECT', wait=15)
A3la.ExpectError

During handling of the above exception, another exception occurred:

Traceback (most recent call last):
  File "/home/debian/code/Rud.py", line 51, in call
    a3la.expect('CONNECT', wait=15)
A3la.ExpectError
Traceback (most recent call last):
  File "/home/debian/code/Rud.py", line 51, in call
    a3la.expect('CONNECT', wait=15)
A3la.ExpectError
Traceback (most recent call last):
  File "/home/debian/code/Rud.py", line 51, in call
    a3la.expect('CONNECT', wait=15)
A3la.ExpectError

During handling of the above exception, another exception occurred:

Traceback (most recent call last):
  File "/home/debian/code/Rud.py", line 51, in call
    a3la.expect('CONNECT', wait=15)
A3la.ExpectError
Traceback (most recent call last):
  File "/home/debian/code/Rud.py", line 51, in call
    a3la.expect('CONNECT', wait=15)
A3la.ExpectError

During handling of the above exception, another exception occurred:

Traceback (most recent call last):
  File "/home/debian/code/Rud.py", line 51, in call
    a3la.expect('CONNECT', wait=15)
A3la.ExpectError

During handling of the above exception, another exception occurred:

Traceback (most recent call last):
  File "/home/debian/code/Rud.py", line 51, in call
    a3la.expect('CONNECT', wait=15)
A3la.ExpectError
Traceback (most recent call last):
  File "/home/debian/code/Rud.py", line 51, in call
    a3la.expect('CONNECT', wait=15)
A3la.ExpectError

During handling of the above exception, another exception occurred:

Traceback (most recent call last):
  File "/home/debian/code/Rud.py", line 51, in call
    a3la.expect('CONNECT', wait=15)
A3la.ExpectError

During handling of the above exception, another exception occurred:

Traceback (most recent call last):
  File "/home/debian/code/Rud.py", line 51, in call
    a3la.expect('CONNECT', wait=15)
A3la.ExpectError

During handling of the above exception, another exception occurred:

Traceback (most recent call last):
  File "/home/debian/code/Rud.py", line 51, in call
    a3la.expect('CONNECT', wait=15)
A3la.ExpectError
Traceback (most recent call last):
  File "/home/debian/code/Gps.py", line 28, in query
    l = self.a3la.expectlines('CSQ')
A3la.ExpectError
Traceback (most recent call last):
  File "/home/debian/code/Rud.py", line 47, in call
    a3la.expect('OK')
A3la.ExpectError
Traceback (most recent call last):
  File "/home/debian/code/Rud.py", line 47, in call
    a3la.expect('OK')
A3la.ExpectError

During handling of the above exception, another exception occurred:

Traceback (most recent call last):
  File "/home/debian/code/Rud.py", line 51, in call
    a3la.expect('CONNECT', wait=15)
A3la.ExpectError
Traceback (most recent call last):
  File "/home/debian/code/Rud.py", line 47, in call
    a3la.expect('OK')
A3la.ExpectError

During handling of the above exception, another exception occurred:

Traceback (most recent call last):
  File "/home/debian/code/Rud.py", line 51, in call
    a3la.expect('CONNECT', wait=15)
A3la.ExpectError

During handling of the above exception, another exception occurred:

Traceback (most recent call last):
  File "/home/debian/code/Rud.py", line 51, in call
    a3la.expect('CONNECT', wait=15)
A3la.ExpectError
Traceback (most recent call last):
  File "/home/debian/code/Rud.py", line 47, in call
    a3la.expect('OK')
A3la.ExpectError

During handling of the above exception, another exception occurred:

Traceback (most recent call last):
  File "/home/debian/code/Rud.py", line 51, in call
    a3la.expect('CONNECT', wait=15)
A3la.ExpectError

During handling of the above exception, another exception occurred:

Traceback (most recent call last):
  File "/home/debian/code/Rud.py", line 51, in call
    a3la.expect('CONNECT', wait=15)
A3la.ExpectError

During handling of the above exception, another exception occurred:

Traceback (most recent call last):
  File "/home/debian/code/Rud.py", line 51, in call
    a3la.expect('CONNECT', wait=15)
A3la.ExpectError
Traceback (most recent call last):
  File "/home/debian/code/Rud.py", line 51, in call
    a3la.expect('CONNECT', wait=15)
A3la.ExpectError
Traceback (most recent call last):
  File "/home/debian/code/Rud.py", line 51, in call
    a3la.expect('CONNECT', wait=15)
A3la.ExpectError
Traceback (most recent call last):
  File "/home/debian/code/Rud.py", line 51, in call
    a3la.expect('CONNECT', wait=15)
A3la.ExpectError

During handling of the above exception, another exception occurred:

Traceback (most recent call last):
  File "/home/debian/code/Rud.py", line 51, in call
    a3la.expect('CONNECT', wait=15)
A3la.ExpectError
Traceback (most recent call last):
  File "/home/debian/code/Rud.py", line 51, in call
    a3la.expect('CONNECT', wait=15)
A3la.ExpectError

During handling of the above exception, another exception occurred:

Traceback (most recent call last):
  File "/home/debian/code/Rud.py", line 51, in call
    a3la.expect('CONNECT', wait=15)
A3la.ExpectError

During handling of the above exception, another exception occurred:

Traceback (most recent call last):
  File "/home/debian/code/Rud.py", line 51, in call
    a3la.expect('CONNECT', wait=15)
A3la.ExpectError
Traceback (most recent call last):
  File "/home/debian/code/Rud.py", line 51, in call
    a3la.expect('CONNECT', wait=15)
A3la.ExpectError

During handling of the above exception, another exception occurred:

Traceback (most recent call last):
  File "/home/debian/code/Rud.py", line 51, in call
    a3la.expect('CONNECT', wait=15)
A3la.ExpectError

During handling of the above exception, another exception occurred:

Traceback (most recent call last):
  File "/home/debian/code/Rud.py", line 51, in call
    a3la.expect('CONNECT', wait=15)
A3la.ExpectError

During handling of the above exception, another exception occurred:

Traceback (most recent call last):
  File "/home/debian/code/Rud.py", line 51, in call
    a3la.expect('CONNECT', wait=15)
A3la.ExpectError
Traceback (most recent call last):
  File "/home/debian/code/Rud.py", line 55, in call
    a3la.expect('done', wait=20)
A3la.ExpectError
Traceback (most recent call last):
  File "/home/debian/code/Rud.py", line 55, in call
    a3la.expect('done', wait=20)
A3la.ExpectError

During handling of the above exception, another exception occurred:

Traceback (most recent call last):
  File "/home/debian/code/Rud.py", line 51, in call
    a3la.expect('CONNECT', wait=15)
A3la.ExpectError
Traceback (most recent call last):
  File "/home/debian/code/Rud.py", line 55, in call
    a3la.expect('done', wait=20)
A3la.ExpectError
Traceback (most recent call last):
  File "/home/debian/code/Rud.py", line 55, in call
    a3la.expect('done', wait=20)
